Workbook

Sheet Sheet1
A1: Company | B1: Location | C1: $Name | D1: Sales Person | E1: Credit Period | F1: Credit Limit | G1: Openning Apr-25
A2: Enterprise | B2: Noida | C2: A N CREATION | D2: KHURSHID JI | E2: 45 Days | F2: 800000 | G2: 0
A3: O-tec | B3: Noida | C3: A N CREATION | D3: KHURSHID JI | E3: 45 Days | F3: 800000 | G3: 86376
A4: O-tec | B4: Surat | C4: A N CREATION | D4: KHURSHID JI | F4: 0 | G4: 0
A5: Enterprise | B5: Surat | C5: A S TRADING | D5: OTHERS | E5: 60 Days | F5: 0 | G5: 0
A6: O-tec | B6: Surat | C6: A S TRADING | D6: OTHERS | F6: 0 | G6: 0
A7: O-tec | B7: Surat | C7: A.I DIGITAL PRINT | D7: PURAV SHAH | E7: 45 Days | F7: 350000 | G7: 0
A8: O-tec | B8: Surat | C8: A.N.CREATION - MACHINE | D8: KHURSHID JI | F8: 0 | G8: 0
A9: Enterprise | B9: Noida | C9: AAD SACH CREATIONS | D9: OTHERS | F9: 0 | G9: 0
A10: O-tec | B10: Surat | C10: AAD SACH CREATIONS | D10: OTHERS | F10: 0 | G10: -500000
A11: O-tec | B11: Noida | C11: AAD SACH CREATIONS | D11: OTHERS | F11: 0 | G11: 0
A12: Enterprise | B12: Surat | C12: AADESH DIGITAL PRINTS | D12: PURAV SHAH | E12: 60 | F12: 50000 | G12: 0
A13: O-tec | B13: Surat | C13: AADESH DIGITAL PRINTS | D13: PURAV SHAH | E13: 60 Days | F13: 500000 | G13: 515011
A14: O-tec | B14: Surat | C14: AADESH DIGITAL PRINTS-MACHINE | D14: PURAV SHAH | F14: 0 | G14: 0
A15: O-tec | B15: Surat | C15: AAKASH FASHION PRINTS PVT LTD | D15: DHANANJAY | E15: 2 Days | F15: 1500000 | G15: 1047132
A16: O-tec | B16: Surat | C16: AAKASH FASHION PRINTS PVT LTD- MACHINE | D16: DHANANJAY | F16: 0 | G16: 0
A17: O-tec | B17: Surat | C17: AAR KAY GRAPHICS | D17: OTHERS | F17: 0 | G17: 0
A18: O-tec | B18: Surat | C18: AARNA FASHION | D18: OTHERS | E18: 45 Days | F18: 950000 | G18: 0
A19: Enterprise | B19: Surat | C19: AARNAV FASHIONS LIMITED | D19: NAKUL JI | E19: 7 Days | F19: 2500000 | G19: 0
A20: O-tec | B20: Surat | C20: AARNAV FASHIONS LIMITED | D20: NAKUL JI | E20: 60 Days | F20: 7200000 | G20: 1041254
A21: O-tec | B21: Surat | C21: AARNAV FASHIONS LIMITED-Machine | D21: NAKUL JI | F21: 0 | G21: 0
A22: O-tec | B22: Surat | C22: AASIYA CREATION | D22: OTHERS | E22: 45 Days | F22: 400000 | G22: 0
A23: O-tec | B23: Noida | C23: AAYUSH RATHI | D23: OTHERS | F23: 0 | G23: 0
A24: O-tec | B24: Surat | C24: AAYUSH SIR | D24: OTHERS | F24: 0 | G24: 0
A25: O-tec | B25: Surat | C25: ABHISEKH TEXCHEM PVT LTD. | D25: OTHERS | F25: 0 | G25: 0
A26: O-tec | B26: Surat | C26: ABHISEKH TEXCHEM PVT LTD-MACHINE | D26: OTHERS | F26: 0 | G26: 300000
A27: O-tec | B27: Surat | C27: ACCRUED REVENUE | D27: OTHERS | F27: 0 | G27: 2534400
A28: O-tec | B28: Surat | C28: ACS TEXTILES (BANGLADESH) LTD | D28: OTHERS | F28: 0 | G28: 0
A29: Enterprise | B29: Surat | C29: ADIYA DESIGNER | D29: NAKUL JI | E29: 60 Days | F29: 100000 | G29: 0
A30: O-tec | B30: Surat | C30: ADIYA DESIGNER | D30: NAKUL JI | E30: 60 Days | F30: 4000000 | G30: 2502447
A31: O-tec | B31: Surat | C31: ADVANCE FORM DEBTORS | D31: OTHERS | F31: 0 | G31: -1956
A32: O-tec | B32: Surat | C32: AEROLAM DECORATIVES LLP | D32: OTHERS | F32: 0 | G32: 0
A33: O-tec | B33: Surat | C33: AGANSA PRIMATAMA. PT | D33: OTHERS | F33: 0 | G33: 0
A34: O-tec | B34: Surat | C34: AIRDOT FAB TEX | D34: OTHERS | F34: 0 | G34: 0
A35: O-tec | B35: Surat | C35: AISHAWARYA CREATIONS | D35: MANMOHAN JI | E35: 30 Days | F35: 600000 | G35: 25025
A36: O-tec | B36: Noida | C36: AISHAWARYA CREATIONS | D36: MANMOHAN JI | E36: 30 Days | F36: 1241782 | G36: 186735
A37: Enterprise | B37: Surat | C37: AJANTA DIGITAL INDUSTRIES | D37: DHANANJAY | F37: 300000 | G37: 0
A38: O-tec | B38: Surat | C38: AJANTA DIGITAL INDUSTRIES-AHMEDABAD | D38: DHANANJAY | F38: 0 | G38: 0
A39: O-tec | B39: Surat | C39: AJANTA DIGITAL INDUSTRIES-SURAT | D39: DHANANJAY | F39: 650000 | G39: 0
A40: O-tec | B40: Surat | C40: AKASH PRASANNAKUMAR SHAH- DOLPHIN DIGITAL | D40: OTHERS | F40: 0 | G40: 0
...

Sheet Sheet3
A1: Company | B1: Location | C1: $Name | D1: Sales Person | E1: Credit Period | F1: Credit Limit | G1: Openning Apr-25 | H1: Outstanding
A2: Enterprise | B2: Noida | C2: A N CREATION | D2: KHURSHID JI | E2: 45 Days | F2: 800000 | G2: 0 | H2: {=XLOOKUP(C:C,Sheet3!A:A,Sheet3!B:B)} -> #N/A
A3: O-tec | B3: Noida | C3: A N CREATION | D3: KHURSHID JI | E3: 45 Days | F3: 800000 | G3: 86376 | H3: {=XLOOKUP(C:C,Sheet3!A:A,Sheet3!B:B)} -> #N/A
A4: O-tec | B4: Surat | C4: A N CREATION | D4: KHURSHID JI | F4: 0 | G4: 0 | H4: {=XLOOKUP(C:C,Sheet3!A:A,Sheet3!B:B)} -> #N/A
A5: Enterprise | B5: Surat | C5: A S TRADING | D5: OTHERS | E5: 60 Days | F5: 0 | G5: 0 | H5: {=XLOOKUP(C:C,Sheet3!A:A,Sheet3!B:B)} -> #N/A
A6: O-tec | B6: Surat | C6: A S TRADING | D6: OTHERS | F6: 0 | G6: 0 | H6: {=XLOOKUP(C:C,Sheet3!A:A,Sheet3!B:B)} -> #N/A
A7: O-tec | B7: Surat | C7: A.I DIGITAL PRINT | D7: PURAV SHAH | E7: 45 Days | F7: 350000 | G7: 0 | H7: {=XLOOKUP(C:C,Sheet3!A:A,Sheet3!B:B)} -> #N/A
A8: O-tec | B8: Surat | C8: A.N.CREATION - MACHINE | D8: KHURSHID JI | F8: 0 | G8: 0 | H8: {=XLOOKUP(C:C,Sheet3!A:A,Sheet3!B:B)} -> #N/A
A9: Enterprise | B9: Noida | C9: AAD SACH CREATIONS | D9: OTHERS | F9: 0 | G9: 0 | H9: 0
A10: O-tec | B10: Surat | C10: AAD SACH CREATIONS | D10: OTHERS | F10: 0 | G10: -500000 | H10: 0
A11: O-tec | B11: Noida | C11: AAD SACH CREATIONS | D11: OTHERS | F11: 0 | G11: 0 | H11: 0
A12: Enterprise | B12: Surat | C12: AADESH DIGITAL PRINTS | D12: PURAV SHAH | E12: 60 | F12: 50000 | G12: 0 | H12: {=XLOOKUP(C:C,Sheet3!A:A,Sheet3!B:B)} -> #N/A
A13: O-tec | B13: Surat | C13: AADESH DIGITAL PRINTS | D13: PURAV SHAH | E13: 60 Days | F13: 500000 | G13: 515011 | H13: {=XLOOKUP(C:C,Sheet3!A:A,Sheet3!B:B)} -> #N/A
A14: O-tec | B14: Surat | C14: AADESH DIGITAL PRINTS-MACHINE | D14: PURAV SHAH | F14: 0 | G14: 0 | H14: 0
A15: O-tec | B15: Surat | C15: AAKASH FASHION PRINTS PVT LTD | D15: DHANANJAY | E15: 2 Days | F15: 1500000 | G15: 1047132 | H15: {=XLOOKUP(C:C,Sheet3!A:A,Sheet3!B:B)} -> #N/A
A16: O-tec | B16: Surat | C16: AAKASH FASHION PRINTS PVT LTD- MACHINE | D16: DHANANJAY | F16: 0 | G16: 0 | H16: 0
A17: O-tec | B17: Surat | C17: AAR KAY GRAPHICS | D17: OTHERS | F17: 0 | G17: 0 | H17: 0
A18: O-tec | B18: Surat | C18: AARNA FASHION | D18: OTHERS | E18: 45 Days | F18: 950000 | G18: 0 | H18: {=XLOOKUP(C:C,Sheet3!A:A,Sheet3!B:B)} -> #N/A
A19: Enterprise | B19: Surat | C19: AARNAV FASHIONS LIMITED | D19: NAKUL JI | E19: 7 Days | F19: 2500000 | G19: 0 | H19: {=XLOOKUP(C:C,Sheet3!A:A,Sheet3!B:B)} -> #N/A
A20: O-tec | B20: Surat | C20: AARNAV FASHIONS LIMITED | D20: NAKUL JI | E20: 60 Days | F20: 7200000 | G20: 1041254 | H20: {=XLOOKUP(C:C,Sheet3!A:A,Sheet3!B:B)} -> #N/A
A21: O-tec | B21: Surat | C21: AARNAV FASHIONS LIMITED-Machine | D21: NAKUL JI | F21: 0 | G21: 0 | H21: {=XLOOKUP(C:C,Sheet3!A:A,Sheet3!B:B)} -> #N/A
A22: O-tec | B22: Surat | C22: AASIYA CREATION | D22: OTHERS | E22: 45 Days | F22: 400000 | G22: 0 | H22: {=XLOOKUP(C:C,Sheet3!A:A,Sheet3!B:B)} -> #N/A
A23: O-tec | B23: Noida | C23: AAYUSH RATHI | D23: OTHERS | F23: 0 | G23: 0 | H23: 0
A24: O-tec | B24: Surat | C24: AAYUSH SIR | D24: OTHERS | F24: 0 | G24: 0 | H24: 0
A25: O-tec | B25: Surat | C25: ABHISEKH TEXCHEM PVT LTD. | D25: OTHERS | F25: 0 | G25: 0 | H25: 0
A26: O-tec | B26: Surat | C26: ABHISEKH TEXCHEM PVT LTD-MACHINE | D26: OTHERS | F26: 0 | G26: 300000 | H26: {=XLOOKUP(C:C,Sheet3!A:A,Sheet3!B:B)} -> #N/A
A27: O-tec | B27: Surat | C27: ACCRUED REVENUE | D27: OTHERS | F27: 0 | G27: 2534400 | H27: 0
A28: O-tec | B28: Surat | C28: ACS TEXTILES (BANGLADESH) LTD | D28: OTHERS | F28: 0 | G28: 0 | H28: 0
A29: Enterprise | B29: Surat | C29: ADIYA DESIGNER | D29: NAKUL JI | E29: 60 Days | F29: 100000 | G29: 0 | H29: {=XLOOKUP(C:C,Sheet3!A:A,Sheet3!B:B)} -> #N/A
A30: O-tec | B30: Surat | C30: ADIYA DESIGNER | D30: NAKUL JI | E30: 60 Days | F30: 4000000 | G30: 2502447 | H30: {=XLOOKUP(C:C,Sheet3!A:A,Sheet3!B:B)} -> #N/A
A31: O-tec | B31: Surat | C31: ADVANCE FORM DEBTORS | D31: OTHERS | F31: 0 | G31: -1956 | H31: 0
A32: O-tec | B32: Surat | C32: AEROLAM DECORATIVES LLP | D32: OTHERS | F32: 0 | G32: 0 | H32: 0
A33: O-tec | B33: Surat | C33: AGANSA PRIMATAMA. PT | D33: OTHERS | F33: 0 | G33: 0 | H33: 0
A34: O-tec | B34: Surat | C34: AIRDOT FAB TEX | D34: OTHERS | F34: 0 | G34: 0 | H34: 0
A35: O-tec | B35: Surat | C35: AISHAWARYA CREATIONS | D35: MANMOHAN JI | E35: 30 Days | F35: 600000 | G35: 25025 | H35: {=XLOOKUP(C:C,Sheet3!A:A,Sheet3!B:B)} -> #N/A
A36: O-tec | B36: Noida | C36: AISHAWARYA CREATIONS | D36: MANMOHAN JI | E36: 30 Days | F36: 1241782 | G36: 186735 | H36: {=XLOOKUP(C:C,Sheet3!A:A,Sheet3!B:B)} -> #N/A
A37: Enterprise | B37: Surat | C37: AJANTA DIGITAL INDUSTRIES | D37: DHANANJAY | F37: 300000 | G37: 0 | H37: {=XLOOKUP(C:C,Sheet3!A:A,Sheet3!B:B)} -> #N/A
A38: O-tec | B38: Surat | C38: AJANTA DIGITAL INDUSTRIES-AHMEDABAD | D38: DHANANJAY | F38: 0 | G38: 0 | H38: {=XLOOKUP(C:C,Sheet3!A:A,Sheet3!B:B)} -> #N/A
A39: O-tec | B39: Surat | C39: AJANTA DIGITAL INDUSTRIES-SURAT | D39: DHANANJAY | F39: 650000 | G39: 0 | H39: {=XLOOKUP(C:C,Sheet3!A:A,Sheet3!B:B)} -> #N/A
A40: O-tec | B40: Surat | C40: AKASH PRASANNAKUMAR SHAH- DOLPHIN DIGITAL | D40: OTHERS | F40: 0 | G40: 0 | H40: 0
...
